Workbook

Sheet characterization
A1: metric | B1: TT_500MHz | C1: TT_750MHz | D1: TT_1000MHz | E1: FF_500MHz | F1: FF_750MHz | G1: FF_1000MHz | H1: SS_500MHz | I1: SS_750MHz | J1: SS_1000MHz
A2: Period (ps) | B2: 2000 | C2: 1333.3 | D2: 1000 | E2: 2000 | F2: 1333.3 | G2: 1000 | H2: 2000 | I2: 1333.3 | J2: 1000
A3: Clock-to-Out (Tcq + Tsu, ps) | B3: 16.59 | C3: 16.59 | D3: 16.59 | E3: 10.53 | F3: 10.53 | G3: 10.53 | H3: 22.73 | I3: 22.73 | J3: 22.73
A5: Max combinational levels per cycle
A6: Max NAND levels | B6: 273 | C6: 181 | D6: 135 | E6: 335 | F6: 223 | G6: 166 | H6: 172 | I6: 114 | J6: 85
A7: Max XOR levels | B7: 74 | C7: 49 | D7: 36 | E7: 124 | F7: 82 | G7: 61 | H7: 49 | I7: 33 | J7: 24
A8: Max MUX levels | B8: 121 | C8: 80 | D8: 60 | E8: 180 | F8: 120 | G8: 89 | H8: 79 | I8: 52 | J8: 39
A9: Max CARRY levels | B9: 64 | C9: 42 | D9: 31 | E9: 94 | F9: 63 | G9: 47 | H9: 43 | I9: 28 | J9: 21
A10: Max MULT levels (PROXY for mixed-bag logic) | B10: 66 | C10: 43 | D10: 32 | E10: 91 | F10: 60 | G10: 45 | H10: 52 | I10: 35 | J10: 26
A11: Max GRAY_CTR levels | B11: 33 | C11: 22 | D11: 16 | E11: 29 | F11: 19 | G11: 14 | H11: 21 | I11: 14 | J11: 10
A12: Max QUEUE levels | B12: 171 | C12: 113 | D12: 84 | E12: 49 | F12: 32 | G12: 24 | H12: 36 | I12: 24 | J12: 18
A14: Per-level gate delay (ps) - freq-independent
A15: per NAND delay (ps) | B15: 7.25 | C15: 7.25 | D15: 7.25 | E15: 5.93 | F15: 5.93 | G15: 5.93 | H15: 11.47 | I15: 11.47 | J15: 11.47
A16: per XOR delay (ps) | B16: 26.77 | C16: 26.77 | D16: 26.77 | E16: 16.01 | F16: 16.01 | G16: 16.01 | H16: 39.69 | I16: 39.69 | J16: 39.69
A17: per MUX delay (ps) | B17: 16.29 | C17: 16.29 | D17: 16.29 | E17: 11 | F17: 11 | G17: 11 | H17: 24.97 | I17: 24.97 | J17: 24.97
A18: per CARRY delay (ps) | B18: 30.77 | C18: 30.77 | D18: 30.77 | E18: 20.97 | F18: 20.97 | G18: 20.97 | H18: 45.22 | I18: 45.22 | J18: 45.22
A19: per MULT delay (ps) (PROXY) | B19: 29.95 | C19: 29.95 | D19: 29.95 | E19: 21.75 | F19: 21.75 | G19: 21.75 | H19: 37.44 | I19: 37.44 | J19: 37.44
A20: per GRAY_CTR delay (ps) | B20: 58.44 | C20: 58.44 | D20: 58.44 | E20: 66.65 | F20: 66.65 | G20: 66.65 | H20: 90.34 | I20: 90.34 | J20: 90.34
A21: per QUEUE delay (ps) | B21: 11.57 | C21: 11.57 | D21: 11.57 | E21: 40.17 | F21: 40.17 | G21: 40.17 | H21: 54.23 | I21: 54.23 | J21: 54.23
A23: Reference single-point delays (ps) - degenerate slope, no per-level number
A24: INV flop-to-flop delay (ps) | B24: 14.47 | C24: 14.47 | D24: 14.47 | E24: 12.22 | F24: 12.22 | G24: 12.22 | H24: 22.33 | I24: 22.33 | J24: 22.33
A25: CLK_DIV flop-to-flop delay (ps) | B25: 21.05 | C25: 21.05 | D25: 21.05 | E25: 16.61 | F25: 16.61 | G25: 16.61 | H25: 31.29 | I25: 31.29 | J25: 31.29
A27: Wire delay per mm by metal layer (buffered route, ps/mm) - cross-partition route estimate
A28: M2/M3 (local / intermediate) | B28: 120 | C28: 120 | D28: 120 | E28: 96 | F28: 96 | G28: 96 | H28: 156 | I28: 156 | J28: 156
A29: M4/M5 (semi-global) | B29: 65 | C29: 65 | D29: 65 | E29: 52 | F29: 52 | G29: 52 | H29: 84.5 | I29: 84.5 | J29: 84.5
A30: M6/M7 (global) | B30: 40 | C30: 40 | D30: 40 | E30: 32 | F30: 32 | G30: 32 | H30: 52 | I30: 52 | J30: 52
A31: M8/M9 (thick) | B31: 22 | C31: 22 | D31: 22 | E31: 17.6 | F31: 17.6 | G31: 17.6 | H31: 28.6 | I31: 28.6 | J31: 28.6
A33: Notes
A34: Probe corner_freq columns are independent measurements (see Per-level table above).
A35: Tflop = Tcq + Tsu derived from NAND chain two-point probe (LEVELS={3,6}).
A36: max_levels = floor((period_ps - Tflop) / per_level_delay).
A37: ** When the critical path is a mixed bag of cells (typical for datapath / FSM next-state / arbitration logic), use the MULT per-level number. It bakes in AND / XOR / full-adder / carry mix.
A38: INV: ABC's strash collapses inverter pairs across the chain, so lev doesn't change between probe sizes - per-level slope is degenerate. Single-point delay is reported in the reference table.
A39: CLK_DIV: critical path is intra-stage (counter + pickoff), so NUM_STAGES doesn't move lev. Single-point delay is reported in the reference table.
A40: Wire delays are 7nm industry rule-of-thumb for buffered routes; the ASAP7 NLDM ships no wire_load table so ABC measured gate delay only. For partition-to-partition output budgeting, look up the destination metal layer and multiply by route length (mm).
A41: Raw probe data is in work/timing_char_data.csv. Reproducer is work/timing_char_sweep.py.

Sheet building blocks
A1: block | B1: P1 | C1: P2 | D1: P3 | E1: P4 | F1: P5 | G1: P6 | H1: params | I1: flop_count | J1: NAND_eq_gates | K1: in MUX lv | L1: in NAND lv | M1: data->D TT (ps) | N1: data->D FF (ps) | O1: data->D SS (ps) | P1: out MUX lv | Q1: out NAND lv | R1: flop->out TT (ps) | S1: flop->out FF (ps) | T1: flop->out SS (ps) | U1: fmax TT (MHz) | V1: fmax FF (MHz) | W1: fmax SS (MHz) | X1: notes
A2: SRAMs
A3: SRAM (raw macro) | B3: 512 | C3: 512 | H3: P1=W, P2=D | I3: 0 | J3: =4*B3 + 8*CEILING(LOG(C3,2),1) | K3: 0 | L3: 1 | M3: =K3*characterization!$D$17 + L3*characterization!$D$15 | N3: =K3*characterization!$G$17 + L3*characterization!$G$15 | O3: =K3*characterization!$J$17 + L3*characterization!$J$15 | P3: 0 | Q3: 1 | R3: =P3*characterization!$D$17 + Q3*characterization!$D$15 | S3: =P3*characterization!$G$17 + Q3*characterization!$G$15 | T3: =P3*characterization!$J$17 + Q3*characterization!$J$15 | U3: =ROUND(1000000/(MAX(M3,R3) + characterization!$D$3), 0) | V3: =ROUND(1000000/(MAX(N3,S3) + characterization!$G$3), 0) | W3: =ROUND(1000000/(MAX(O3,T3) + characterization!$J$3), 0) | X3: SRAM macro (single-port, synchronous read). Storage = W*D bits goes to the macro, not flop count. Read latency = 1 cycle (data appears next clock). Replace this row's per-bit delay with vendor SRAM datasheet for accurate timing.
A4: gaxi_fifo_sync (REG=1, SRAM-backed) | B4: 512 | C4: 512 | H4: P1=W, P2=D | I4: =3*CEILING(LOG(C4,2),1) + 1 | J4: =B4*4 + CEILING(LOG(C4,2),1)*8 + 20 | K4: 0 | L4: 1 | M4: =K4*characterization!$D$17 + L4*characterization!$D$15 | N4: =K4*characterization!$G$17 + L4*characterization!$G$15 | O4: =K4*characterization!$J$17 + L4*characterization!$J$15 | P4: 0 | Q4: 1 | R4: =P4*characterization!$D$17 + Q4*characterization!$D$15 | S4: =P4*characterization!$G$17 + Q4*characterization!$G$15 | T4: =P4*characterization!$J$17 + Q4*characterization!$J$15 | U4: =ROUND(1000000/(MAX(M4,R4) + characterization!$D$3), 0) | V4: =ROUND(1000000/(MAX(N4,S4) + characterization!$G$3), 0) | W4: =ROUND(1000000/(MAX(O4,T4) + characterization!$J$3), 0) | X4: REGISTERED=1 + MEM_STYLE=BRAM: storage is in an SRAM/BRAM macro, not flops. Used only by SRAM controller units in STREAM/RAPIDS. Storage bits = W*D. fmax is limited by the SRAM macro clock-to-Q, not by std-cell timing.
A5: Building Blocks
A6: gaxi_skid_buffer | B6: 1 | C6: 2 | H6: P1=W, P2=D | I6: =B6*C6 + C6 + 2 | J6: =B6*C6*4 + 10 | K6: 1 | L6: 1 | M6: =K6*characterization!$D$17 + L6*characterization!$D$15 | N6: =K6*characterization!$G$17 + L6*characterization!$G$15 | O6: =K6*characterization!$J$17 + L6*characterization!$J$15 | P6: 0 | Q6: 0 | R6: =P6*characterization!$D$17 + Q6*characterization!$D$15 | S6: =P6*characterization!$G$17 + Q6*characterization!$G$15 | T6: =P6*characterization!$J$17 + Q6*characterization!$J$15 | U6: =ROUND(1000000/(MAX(M6,R6) + characterization!$D$3), 0) | V6: =ROUND(1000000/(MAX(N6,S6) + characterization!$G$3), 0) | W6: =ROUND(1000000/(MAX(O6,T6) + characterization!$J$3), 0) | X6: Skid buffer outputs come straight from the head flop Q - no output muxing. Input side has the bypass MUX2. Flops = W*D storage + D valid + 2 control.
A7: gaxi_fifo_sync (REG=0) | B7: 1 | C7: 2 | H7: P1=W, P2=D | I7: =B7*C7 + 3*CEILING(LOG(C7,2),1) + 1 | J7: =B7*C7*6 + CEILING(LOG(C7,2),1)*8 + 20 | K7: 1 | L7: 2 | M7: =K7*characterization!$D$17 + L7*characterization!$D$15 | N7: =K7*characterization!$G$17 + L7*characterization!$G$15 | O7: =K7*characterization!$J$17 + L7*characterization!$J$15 | P7: =CEILING(LOG(C7,2),1) | Q7: 0 | R7: =P7*characterization!$D$17 + Q7*characterization!$D$15 | S7: =P7*characterization!$G$17 + Q7*characterization!$G$15 | T7: =P7*characterization!$J$17 + Q7*characterization!$J$15 | U7: =ROUND(1000000/(MAX(M7,R7) + characterization!$D$3), 0) | V7: =ROUND(1000000/(MAX(N7,S7) + characterization!$G$3), 0) | W7: =ROUND(1000000/(MAX(O7,T7) + characterization!$J$3), 0) | X7: Output critical path is the READ mux tree, depth=log2(D). Flops = W*D storage + 3*log2(D) ptrs/count + 1 state. Default FIFO in STREAM/RAPIDS (non-SRAM-backed).
A8: arbiter_round_robin | B8: 2 | H8: P1=N | I8: =B8 + 2 | J8: =B8*8 | K8: 0 | L8: 1 | M8: =K8*characterization!$D$17 + L8*characterization!$D$15 | N8: =K8*characterization!$G$17 + L8*characterization!$G$15 | O8: =K8*characterization!$J$17 + L8*characterization!$J$15 | P8: =CEILING(LOG(B8,2),1) | Q8: 1 | R8: =P8*characterization!$D$17 + Q8*characterization!$D$15 | S8: =P8*characterization!$G$17 + Q8*characterization!$G$15 | T8: =P8*characterization!$J$17 + Q8*characterization!$J$15 | U8: =ROUND(1000000/(MAX(M8,R8) + characterization!$D$3), 0) | V8: =ROUND(1000000/(MAX(N8,S8) + characterization!$G$3), 0) | W8: =ROUND(1000000/(MAX(O8,T8) + characterization!$J$3), 0) | X8: Priority encoder is log2(N) MUX levels on the OUTPUT side (req -> encode -> gnt). Flops = N (last-grant tracker) + 2.
A9: axi4_master_rd | B9: 32 | C9: 32 | D9: 4 | E9: 1 | F9: 2 | G9: 2 | H9: P1=AW, P2=DW, P3=IW, P4=UW, P5=SKID_AR, P6=SKID_R | I9: =F9*(B9+D9+E9+29) + G9*(D9+C9+E9+3) | J9: =4*(F9*(B9+D9+E9+29) + G9*(D9+C9+E9+3)) | K9: 1 | L9: 1 | M9: =K9*characterization!$D$17 + L9*characterization!$D$15 | N9: =K9*characterization!$G$17 + L9*characterization!$G$15 | O9: =K9*characterization!$J$17 + L9*characterization!$J$15 | P9: 1 | Q9: 1 | R9: =P9*characterization!$D$17 + Q9*characterization!$D$15 | S9: =P9*characterization!$G$17 + Q9*characterization!$G$15 | T9: =P9*characterization!$J$17 + Q9*characterization!$J$15 | U9: =ROUND(1000000/(MAX(M9,R9) + characterization!$D$3), 0) | V9: =ROUND(1000000/(MAX(N9,S9) + characterization!$G$3), 0) | W9: =ROUND(1000000/(MAX(O9,T9) + characterization!$J$3), 0) | X9: Two skid buffers in series (AR + R). Input bypass MUX2 + output select MUX2. Flops scale with SKID_AR*ARw + SKID_R*Rw.
A10: axi4_master_wr | B10: 32 | C10: 32 | D10: 4 | E10: 1 | F10: 2 | G10: 2 | H10: P1=AW, P2=DW, P3=IW, P4=UW, P5=SKID_AW, P6=SKID_W | I10: =F10*(B10+D10+E10+29) + G10*(C10+C10/8+E10+1) + 2*(D10+E10+2) | J10: =4*(F10*(B10+D10+E10+29) + G10*(C10+C10/8+E10+1) + 2*(D10+E10+2)) | K10: 1 | L10: 1 | M10: =K10*characterization!$D$17 + L10*characterization!$D$15 | N10: =K10*characterization!$G$17 + L10*characterization!$G$15 | O10: =K10*characterization!$J$17 + L10*characterization!$J$15 | P10: 1 | Q10: 1 | R10: =P10*characterization!$D$17 + Q10*characterization!$D$15 | S10: =P10*characterization!$G$17 + Q10*characterization!$G$15 | T10: =P10*characterization!$J$17 + Q10*characterization!$J$15 | U10: =ROUND(1000000/(MAX(M10,R10) + characterization!$D$3), 0) | V10: =ROUND(1000000/(MAX(N10,S10) + characterization!$G$3), 0) | W10: =ROUND(1000000/(MAX(O10,T10) + characterization!$J$3), 0) | X10: Three skid buffers (AW + W + B); SKID_B fixed at 2 in this row. Input bypass + output select MUXes; both are 1 level.
A12: SRAM storage size reference
A13: SRAM raw macro: storage bits = W * D = | D13: =B3*C3 | E13: bits = | F13: =B3*C3/8/1024 | G13: KB
A14: FIFO REG=1 SRAM-backed: storage bits = W * D = | D14: =B4*C4 | E14: bits = | F14: =B4*C4/8/1024 | G14: KB
A16: Cell coding
A17: Yellow = editable param
A18: Grey = derived formula
A20: data->D = critical combinational delay on the path that loads the downstream flop. Compare against (period - Tflop) to size for a freq.
A21: Estimates are first-order: structural flop/gate counts + characterization per-level delays. Treat them as design-time SWAGs, not post-synth truth.
A22: REG=1 SRAM-backed FIFO is only used by SRAM controller units in STREAM/RAPIDS (sram_controller_unit, src/snk_sram_controller_unit_beats). Everywhere else uses REG=0 - that's why the Building Blocks section lists only the REG=0 variant.

Sheet stream
A1: FUB | B1: port | C1: dir | D1: building block crossed | E1: MUX lv | F1: NAND lv | G1: source/sink flop or BB port | H1: local delay TT (ps) | I1: local delay FF (ps) | J1: local delay SS (ps) | K1: places it goes (consumer / producer)
A2: stream_latency_bridge
A3: stream_latency_bridge | B3: s_valid | C3: in | E3: 1 | F3: 1 | G3: r_drain_ip flop D | H3: =E3*characterization!$D$17 + F3*characterization!$D$15 | I3: =E3*characterization!$G$17 + F3*characterization!$G$15 | J3: =E3*characterization!$J$17 + F3*characterization!$J$15 | K3: from u_channel_fifo.rd_valid in sram_controller_unit
A4: stream_latency_bridge | B4: s_data[DW-1:0] | C4: in | D4: gaxi_fifo_sync | E4: 0 | F4: 0 | G4: u_skid_buffer.wr_data | H4: =E4*characterization!$D$17 + F4*characterization!$D$15 | I4: =E4*characterization!$G$17 + F4*characterization!$G$15 | J4: =E4*characterization!$J$17 + F4*characterization!$J$15 | K4: from u_channel_fifo.rd_data
A5: stream_latency_bridge | B5: s_ready | C5: out | E5: 1 | F5: 2 | G5: comb of skid count + drain | H5: =E5*characterization!$D$17 + F5*characterization!$D$15 | I5: =E5*characterization!$G$17 + F5*characterization!$G$15 | J5: =E5*characterization!$J$17 + F5*characterization!$J$15 | K5: to u_channel_fifo.rd_ready
A6: stream_latency_bridge | B6: m_valid | C6: out | D6: gaxi_fifo_sync | E6: 0 | F6: 0 | G6: u_skid_buffer.rd_valid | H6: =E6*characterization!$D$17 + F6*characterization!$D$15 | I6: =E6*characterization!$G$17 + F6*characterization!$G$15 | J6: =E6*characterization!$J$17 + F6*characterization!$J$15 | K6: to axi_write_engine.sram_rd_valid
A7: stream_latency_bridge | B7: m_data[DW-1:0] | C7: out | D7: gaxi_fifo_sync | E7: 0 | F7: 0 | G7: u_skid_buffer.rd_data | H7: =E7*characterization!$D$17 + F7*characterization!$D$15 | I7: =E7*characterization!$G$17 + F7*characterization!$G$15 | J7: =E7*characterization!$J$17 + F7*characterization!$J$15 | K7: to axi_write_engine.sram_rd_data
A8: stream_latency_bridge | B8: m_ready | C8: in | D8: gaxi_fifo_sync | E8: 0 | F8: 0 | G8: u_skid_buffer.rd_ready | H8: =E8*characterization!$D$17 + F8*characterization!$D$15 | I8: =E8*characterization!$G$17 + F8*characterization!$G$15 | J8: =E8*characterization!$J$17 + F8*characterization!$J$15 | K8: from axi_write_engine.sram_rd_ready
A9: stream_latency_bridge | B9: occupancy[2:0] | C9: out | D9: gaxi_fifo_sync | E9: 0 | F9: 0 | G9: u_skid_buffer.count | H9: =E9*characterization!$D$17 + F9*characterization!$D$15 | I9: =E9*characterization!$G$17 + F9*characterization!$G$15 | J9: =E9*characterization!$J$17 + F9*characterization!$J$15 | K9: to scheduler (drain-IP backpressure)
A10: stream_alloc_ctrl
A11: stream_alloc_ctrl | B11: wr_valid | C11: in | E11: 0 | F11: 1 | G11: r_wr_ptr flop D (+wr_size) | H11: =E11*characterization!$D$17 + F11*characterization!$D$15 | I11: =E11*characterization!$G$17 + F11*characterization!$G$15 | J11: =E11*characterization!$J$17 + F11*characterization!$J$15 | K11: from axi_read_engine (allocate request)
A12: stream_alloc_ctrl | B12: wr_size[7:0] | C12: in | E12: 0 | F12: 1 | G12: r_wr_ptr adder input | H12: =E12*characterization!$D$17 + F12*characterization!$D$15 | I12: =E12*characterization!$G$17 + F12*characterization!$G$15 | J12: =E12*characterization!$J$17 + F12*characterization!$J$15 | K12: from axi_read_engine
A13: stream_alloc_ctrl | B13: rd_valid | C13: in | E13: 0 | F13: 1 | G13: r_rd_ptr flop D | H13: =E13*characterization!$D$17 + F13*characterization!$D$15 | I13: =E13*characterization!$G$17 + F13*characterization!$G$15 | J13: =E13*characterization!$J$17 + F13*characterization!$J$15 | K13: from sram_controller_unit (release event)
A14: stream_alloc_ctrl | B14: space_free[AW:0] | C14: out | E14: 0 | F14: 0 | G14: r_space_free (registered) | H14: =E14*characterization!$D$17 + F14*characterization!$D$15 | I14: =E14*characterization!$G$17 + F14*characterization!$G$15 | J14: =E14*characterization!$J$17 + F14*characterization!$J$15 | K14: to axi_read_engine (sram_alloc_space_free)
A15: stream_alloc_ctrl | B15: wr_full | C15: out | E15: 0 | F15: 1 | G15: comb of r_space_free | H15: =E15*characterization!$D$17 + F15*characterization!$D$15 | I15: =E15*characterization!$G$17 + F15*characterization!$G$15 | J15: =E15*characterization!$J$17 + F15*characterization!$J$15 | K15: to axi_read_engine (back-pressure)
A16: stream_alloc_ctrl | B16: wr_almost_full | C16: out | E16: 0 | F16: 1 | G16: comb of r_space_free | H16: =E16*characterization!$D$17 + F16*characterization!$D$15 | I16: =E16*characterization!$G$17 + F16*characterization!$G$15 | J16: =E16*characterization!$J$17 + F16*characterization!$J$15 | K16: to axi_read_engine (threshold)
A17: stream_alloc_ctrl | B17: rd_empty | C17: out | E17: 0 | F17: 1 | G17: comb of r_space_free | H17: =E17*characterization!$D$17 + F17*characterization!$D$15 | I17: =E17*characterization!$G$17 + F17*characterization!$G$15 | J17: =E17*characterization!$J$17 + F17*characterization!$J$15 | K17: unused (debug)
A18: stream_drain_ctrl
A19: stream_drain_ctrl | B19: wr_valid | C19: in | E19: 0 | F19: 1 | G19: r_wr_ptr flop D | H19: =E19*characterization!$D$17 + F19*characterization!$D$15 | I19: =E19*characterization!$G$17 + F19*characterization!$G$15 | J19: =E19*characterization!$J$17 + F19*characterization!$J$15 | K19: from u_channel_fifo handshake in sram_controller_unit
A20: stream_drain_ctrl | B20: rd_valid | C20: in | E20: 0 | F20: 1 | G20: r_rd_ptr flop D (+rd_size) | H20: =E20*characterization!$D$17 + F20*characterization!$D$15 | I20: =E20*characterization!$G$17 + F20*characterization!$G$15 | J20: =E20*characterization!$J$17 + F20*characterization!$J$15 | K20: from axi_write_engine (drain reservation)
A21: stream_drain_ctrl | B21: rd_size[7:0] | C21: in | E21: 0 | F21: 1 | G21: r_rd_ptr adder input | H21: =E21*characterization!$D$17 + F21*characterization!$D$15 | I21: =E21*characterization!$G$17 + F21*characterization!$G$15 | J21: =E21*characterization!$J$17 + F21*characterization!$J$15 | K21: from axi_write_engine
A22: stream_drain_ctrl | B22: data_available[AW:0] | C22: out | E22: 0 | F22: 0 | G22: r_data_available (registered) | H22: =E22*characterization!$D$17 + F22*characterization!$D$15 | I22: =E22*characterization!$G$17 + F22*characterization!$G$15 | J22: =E22*characterization!$J$17 + F22*characterization!$J$15 | K22: to axi_write_engine
A23: stream_drain_ctrl | B23: rd_empty | C23: out | E23: 0 | F23: 1 | G23: comb of r_data_available | H23: =E23*characterization!$D$17 + F23*characterization!$D$15 | I23: =E23*characterization!$G$17 + F23*characterization!$G$15 | J23: =E23*characterization!$J$17 + F23*characterization!$J$15 | K23: to axi_write_engine (no data)
A24: stream_drain_ctrl | B24: wr_full | C24: out | E24: 0 | F24: 1 | G24: comb of r_data_available | H24: =E24*characterization!$D$17 + F24*characterization!$D$15 | I24: =E24*characterization!$G$17 + F24*characterization!$G$15 | J24: =E24*characterization!$J$17 + F24*characterization!$J$15 | K24: to sram_controller_unit (back-pressure)
A25: sram_controller_unit
A26: sram_controller_unit | B26: axi_rd_alloc_req | C26: in | E26: 0 | F26: 1 | G26: alloc_ctrl.wr_valid | H26: =E26*characterization!$D$17 + F26*characterization!$D$15 | I26: =E26*characterization!$G$17 + F26*characterization!$G$15 | J26: =E26*characterization!$J$17 + F26*characterization!$J$15 | K26: from axi_read_engine (reserve burst space)
A27: sram_controller_unit | B27: axi_rd_alloc_size[7:0] | C27: in | E27: 0 | F27: 0 | G27: alloc_ctrl.wr_size | H27: =E27*characterization!$D$17 + F27*characterization!$D$15 | I27: =E27*characterization!$G$17 + F27*characterization!$G$15 | J27: =E27*characterization!$J$17 + F27*characterization!$J$15 | K27: from axi_read_engine
A28: sram_controller_unit | B28: axi_rd_alloc_space_free[AW:0] | C28: out | E28: 0 | F28: 0 | G28: alloc_ctrl.space_free | H28: =E28*characterization!$D$17 + F28*characterization!$D$15 | I28: =E28*characterization!$G$17 + F28*characterization!$G$15 | J28: =E28*characterization!$J$17 + F28*characterization!$J$15 | K28: to axi_read_engine
A29: sram_controller_unit | B29: axi_rd_sram_valid | C29: in | D29: gaxi_fifo_sync | E29: 0 | F29: 0 | G29: u_channel_fifo.wr_valid | H29: =E29*characterization!$D$17 + F29*characterization!$D$15 | I29: =E29*characterization!$G$17 + F29*characterization!$G$15 | J29: =E29*characterization!$J$17 + F29*characterization!$J$15 | K29: from axi_read_engine (write data into SRAM FIFO)
A30: sram_controller_unit | B30: axi_rd_sram_data[DW-1:0] | C30: in | D30: gaxi_fifo_sync | E30: 0 | F30: 0 | G30: u_channel_fifo.wr_data | H30: =E30*characterization!$D$17 + F30*characterization!$D$15 | I30: =E30*characterization!$G$17 + F30*characterization!$G$15 | J30: =E30*characterization!$J$17 + F30*characterization!$J$15 | K30: from axi_read_engine
A31: sram_controller_unit | B31: axi_rd_sram_ready | C31: out | D31: gaxi_fifo_sync | E31: 0 | F31: 0 | G31: u_channel_fifo.wr_ready | H31: =E31*characterization!$D$17 + F31*characterization!$D$15 | I31: =E31*characterization!$G$17 + F31*characterization!$G$15 | J31: =E31*characterization!$J$17 + F31*characterization!$J$15 | K31: to axi_read_engine
A32: sram_controller_unit | B32: axi_wr_sram_valid | C32: out | D32: gaxi_fifo_sync | E32: 0 | F32: 0 | G32: u_latency_bridge.m_valid | H32: =E32*characterization!$D$17 + F32*characterization!$D$15 | I32: =E32*characterization!$G$17 + F32*characterization!$G$15 | J32: =E32*characterization!$J$17 + F32*characterization!$J$15 | K32: to axi_write_engine
A33: sram_controller_unit | B33: axi_wr_sram_data[DW-1:0] | C33: out | D33: gaxi_fifo_sync | E33: 0 | F33: 0 | G33: u_latency_bridge.m_data | H33: =E33*characterization!$D$17 + F33*characterization!$D$15 | I33: =E33*characterization!$G$17 + F33*characterization!$G$15 | J33: =E33*characterization!$J$17 + F33*characterization!$J$15 | K33: to axi_write_engine
A34: sram_controller_unit | B34: axi_wr_sram_ready | C34: in | E34: 0 | F34: 0 | G34: u_latency_bridge.m_ready | H34: =E34*characterization!$D$17 + F34*characterization!$D$15 | I34: =E34*characterization!$G$17 + F34*characterization!$G$15 | J34: =E34*characterization!$J$17 + F34*characterization!$J$15 | K34: from axi_write_engine
A35: sram_controller_unit | B35: wr_drain_req | C35: in | E35: 0 | F35: 1 | G35: drain_ctrl.rd_valid | H35: =E35*characterization!$D$17 + F35*characterization!$D$15 | I35: =E35*characterization!$G$17 + F35*characterization!$G$15 | J35: =E35*characterization!$J$17 + F35*characterization!$J$15 | K35: from axi_write_engine
A36: sram_controller
A37: sram_controller | B37: ch_alloc_req[N-1:0] | C37: in | E37: 1 | F37: 1 | G37: per-ch sram_controller_unit | H37: =E37*characterization!$D$17 + F37*characterization!$D$15 | I37: =E37*characterization!$G$17 + F37*characterization!$G$15 | J37: =E37*characterization!$J$17 + F37*characterization!$J$15 | K37: from axi_read_engine (N-channel fan-out)
A38: sram_controller | B38: ch_alloc_space_free[N-1:0][AW:0] | C38: out | E38: 1 | F38: 0 | G38: per-ch alloc.space_free | H38: =E38*characterization!$D$17 + F38*characterization!$D$15 | I38: =E38*characterization!$G$17 + F38*characterization!$G$15 | J38: =E38*characterization!$J$17 + F38*characterization!$J$15 | K38: to axi_read_engine
A39: sram_controller | B39: ch_rd_valid[N-1:0] | C39: in | E39: 1 | F39: 1 | G39: per-ch SRAM FIFO wr | H39: =E39*characterization!$D$17 + F39*characterization!$D$15 | I39: =E39*characterization!$G$17 + F39*characterization!$G$15 | J39: =E39*characterization!$J$17 + F39*characterization!$J$15 | K39: from axi_read_engine
A40: sram_controller | B40: ch_wr_valid[N-1:0] | C40: out | E40: 1 | F40: 0 | G40: per-ch SRAM FIFO read | H40: =E40*characterization!$D$17 + F40*characterization!$D$15 | I40: =E40*characterization!$G$17 + F40*characterization!$G$15 | J40: =E40*characterization!$J$17 + F40*characterization!$J$15 | K40: to axi_write_engine
...
