Workbook

Sheet characterization
A1: metric | B1: TT_2000MHz | C1: TT_2250MHz | D1: TT_2500MHz | E1: TT_2750MHz | F1: TT_3000MHz | G1: FF_2000MHz | H1: FF_2250MHz | I1: FF_2500MHz | J1: FF_2750MHz | K1: FF_3000MHz | L1: SS_2000MHz | M1: SS_2250MHz | N1: SS_2500MHz | O1: SS_2750MHz | P1: SS_3000MHz
A2: Period (ps) | B2: 500 | C2: 444.4 | D2: 400 | E2: 363.6 | F2: 333.3 | G2: 500 | H2: 444.4 | I2: 400 | J2: 363.6 | K2: 333.3 | L2: 500 | M2: 444.4 | N2: 400 | O2: 363.6 | P2: 333.3
A3: Clock-to-Out (Tcq + Tsu, ps) | B3: 16.59 | C3: 16.59 | D3: 16.59 | E3: 16.59 | F3: 16.59 | G3: 10.53 | H3: 10.53 | I3: 10.53 | J3: 10.53 | K3: 10.53 | L3: 22.73 | M3: 22.73 | N3: 22.73 | O3: 22.73 | P3: 22.73
A5: Max combinational levels per cycle
A6: Max NAND levels | B6: 66 | C6: 58 | D6: 52 | E6: 47 | F6: 43 | G6: 82 | H6: 73 | I6: 65 | J6: 59 | K6: 54 | L6: 41 | M6: 36 | N6: 32 | O6: 29 | P6: 27
A7: Max XOR levels | B7: 18 | C7: 15 | D7: 14 | E7: 12 | F7: 11 | G7: 30 | H7: 27 | I7: 24 | J7: 22 | K7: 20 | L7: 12 | M7: 10 | N7: 9 | O7: 8 | P7: 7
A8: Max MUX levels | B8: 29 | C8: 26 | D8: 23 | E8: 21 | F8: 19 | G8: 44 | H8: 39 | I8: 35 | J8: 32 | K8: 29 | L8: 19 | M8: 16 | N8: 15 | O8: 13 | P8: 12
A9: Max CARRY levels | B9: 15 | C9: 13 | D9: 12 | E9: 11 | F9: 10 | G9: 23 | H9: 20 | I9: 18 | J9: 16 | K9: 15 | L9: 10 | M9: 9 | N9: 8 | O9: 7 | P9: 6
A10: Max MULT levels (PROXY for mixed-bag logic) | B10: 16 | C10: 14 | D10: 12 | E10: 11 | F10: 10 | G10: 22 | H10: 19 | I10: 17 | J10: 16 | K10: 14 | L10: 12 | M10: 11 | N10: 10 | O10: 9 | P10: 8
A11: Max GRAY_CTR levels | B11: 8 | C11: 7 | D11: 6 | E11: 5 | F11: 5 | G11: 7 | H11: 6 | I11: 5 | J11: 5 | K11: 4 | L11: 5 | M11: 4 | N11: 4 | O11: 3 | P11: 3
A12: Max QUEUE levels | B12: 41 | C12: 36 | D12: 33 | E12: 29 | F12: 27 | G12: 12 | H12: 10 | I12: 9 | J12: 8 | K12: 8 | L12: 8 | M12: 7 | N12: 6 | O12: 6 | P12: 5
A14: Per-level gate delay (ps) - freq-independent
A15: per NAND delay (ps) | B15: 7.25 | C15: 7.25 | D15: 7.25 | E15: 7.25 | F15: 7.25 | G15: 5.93 | H15: 5.93 | I15: 5.93 | J15: 5.93 | K15: 5.93 | L15: 11.47 | M15: 11.47 | N15: 11.47 | O15: 11.47 | P15: 11.47
A16: per XOR delay (ps) | B16: 26.77 | C16: 26.77 | D16: 26.77 | E16: 26.77 | F16: 26.77 | G16: 16.01 | H16: 16.01 | I16: 16.01 | J16: 16.01 | K16: 16.01 | L16: 39.69 | M16: 39.69 | N16: 39.69 | O16: 39.69 | P16: 39.69
A17: per MUX delay (ps) | B17: 16.29 | C17: 16.29 | D17: 16.29 | E17: 16.29 | F17: 16.29 | G17: 11 | H17: 11 | I17: 11 | J17: 11 | K17: 11 | L17: 24.97 | M17: 24.97 | N17: 24.97 | O17: 24.97 | P17: 24.97
A18: per CARRY delay (ps) | B18: 30.77 | C18: 30.77 | D18: 30.77 | E18: 30.77 | F18: 30.77 | G18: 20.97 | H18: 20.97 | I18: 20.97 | J18: 20.97 | K18: 20.97 | L18: 45.22 | M18: 45.22 | N18: 45.22 | O18: 45.22 | P18: 45.22
A19: per MULT delay (ps) (PROXY) | B19: 29.95 | C19: 29.95 | D19: 29.95 | E19: 29.95 | F19: 29.95 | G19: 21.75 | H19: 21.75 | I19: 21.75 | J19: 21.75 | K19: 21.75 | L19: 37.44 | M19: 37.44 | N19: 37.44 | O19: 37.44 | P19: 37.44
A20: per GRAY_CTR delay (ps) | B20: 58.44 | C20: 58.44 | D20: 58.44 | E20: 58.44 | F20: 58.44 | G20: 66.65 | H20: 66.65 | I20: 66.65 | J20: 66.65 | K20: 66.65 | L20: 90.34 | M20: 90.34 | N20: 90.34 | O20: 90.34 | P20: 90.34
A21: per QUEUE delay (ps) | B21: 11.57 | C21: 11.57 | D21: 11.57 | E21: 11.57 | F21: 11.57 | G21: 40.17 | H21: 40.17 | I21: 40.17 | J21: 40.17 | K21: 40.17 | L21: 54.23 | M21: 54.23 | N21: 54.23 | O21: 54.23 | P21: 54.23
A23: Reference single-point delays (ps) - degenerate slope, no per-level number
A24: INV flop-to-flop delay (ps) | B24: 14.47 | C24: 14.47 | D24: 14.47 | E24: 14.47 | F24: 14.47 | G24: 12.22 | H24: 12.22 | I24: 12.22 | J24: 12.22 | K24: 12.22 | L24: 22.33 | M24: 22.33 | N24: 22.33 | O24: 22.33 | P24: 22.33
A25: CLK_DIV flop-to-flop delay (ps) | B25: 21.05 | C25: 21.05 | D25: 21.05 | E25: 21.05 | F25: 21.05 | G25: 16.61 | H25: 16.61 | I25: 16.61 | J25: 16.61 | K25: 16.61 | L25: 31.29 | M25: 31.29 | N25: 31.29 | O25: 31.29 | P25: 31.29
A27: Design clocks - one row per clock; other sheets VLOOKUP by clock name
A28: clock name | B28: freq (MHz) | C28: target corner | D28: period (ps) | E28: input delay 60% (ps) | F28: output delay 40% (ps) | G28: wire/hop (ps)
A29: clk_main | B29: 1000 | C29: TT | D29: =IF(ISNUMBER(B29), 1000000/B29, "") | E29: =IF(ISNUMBER(B29), D29*0.6, "") | F29: =IF(ISNUMBER(B29), D29*0.4, "") | G29: 100
D30: =IF(ISNUMBER(B30), 1000000/B30, "") | E30: =IF(ISNUMBER(B30), D30*0.6, "") | F30: =IF(ISNUMBER(B30), D30*0.4, "")
D31: =IF(ISNUMBER(B31), 1000000/B31, "") | E31: =IF(ISNUMBER(B31), D31*0.6, "") | F31: =IF(ISNUMBER(B31), D31*0.4, "")
D32: =IF(ISNUMBER(B32), 1000000/B32, "") | E32: =IF(ISNUMBER(B32), D32*0.6, "") | F32: =IF(ISNUMBER(B32), D32*0.4, "")
D33: =IF(ISNUMBER(B33), 1000000/B33, "") | E33: =IF(ISNUMBER(B33), D33*0.6, "") | F33: =IF(ISNUMBER(B33), D33*0.4, "")
D34: =IF(ISNUMBER(B34), 1000000/B34, "") | E34: =IF(ISNUMBER(B34), D34*0.6, "") | F34: =IF(ISNUMBER(B34), D34*0.4, "")
A36: Wire delay per mm by metal layer (buffered route, ps/mm) - cross-partition route estimate
A37: M2/M3 (local / intermediate) | B37: 120 | C37: 120 | D37: 120 | E37: 120 | F37: 120 | G37: 96 | H37: 96 | I37: 96 | J37: 96 | K37: 96 | L37: 156 | M37: 156 | N37: 156 | O37: 156 | P37: 156
A38: M4/M5 (semi-global) | B38: 65 | C38: 65 | D38: 65 | E38: 65 | F38: 65 | G38: 52 | H38: 52 | I38: 52 | J38: 52 | K38: 52 | L38: 84.5 | M38: 84.5 | N38: 84.5 | O38: 84.5 | P38: 84.5
A39: M6/M7 (global) | B39: 40 | C39: 40 | D39: 40 | E39: 40 | F39: 40 | G39: 32 | H39: 32 | I39: 32 | J39: 32 | K39: 32 | L39: 52 | M39: 52 | N39: 52 | O39: 52 | P39: 52
A40: M8/M9 (thick) | B40: 22 | C40: 22 | D40: 22 | E40: 22 | F40: 22 | G40: 17.6 | H40: 17.6 | I40: 17.6 | J40: 17.6 | K40: 17.6 | L40: 28.6 | M40: 28.6 | N40: 28.6 | O40: 28.6 | P40: 28.6
A42: Notes
A43: Probe corner_freq columns are independent measurements (see Per-level table above).
A44: Tflop = Tcq + Tsu derived from NAND chain two-point probe (LEVELS={3,6}).
A45: max_levels = floor((period_ps - Tflop) / per_level_delay).
A46: ** When the critical path is a mixed bag of cells (typical for datapath / FSM next-state / arbitration logic), use the MULT per-level number. It bakes in AND / XOR / full-adder / carry mix.
...

Sheet building blocks
A1: block | B1: P1 | C1: P2 | D1: P3 | E1: P4 | F1: P5 | G1: P6 | H1: params | I1: flop_count | J1: NAND_eq_gates | K1: in MUX lv | L1: in NAND lv | M1: data->D TT (ps) | N1: data->D FF (ps) | O1: data->D SS (ps) | P1: out MUX lv | Q1: out NAND lv | R1: flop->out TT (ps) | S1: flop->out FF (ps) | T1: flop->out SS (ps) | U1: fmax TT (MHz) | V1: fmax FF (MHz) | W1: fmax SS (MHz) | X1: clock | Y1: target period (ps) | Z1: target corner | AA1: target data->D (ps) | AB1: target flop->out (ps) | AC1: delay_in (ps) | AD1: delay_out (ps) | AF1: slack (ps) | AG1: notes
A2: CONFIG | B2: Each row's 'clock' cell (col X) holds a name from characterization's Design clocks table. Period, corner, input 60%, output 40% are all VLOOKUP'd per row. Change the table entry to plan a new freq/corner and watch the slack column flip from negative (fail) to positive (pass).
A3: SRAMs
A4: SRAM (raw macro) | B4: 512 | C4: 512 | H4: P1=W, P2=D | I4: 0 | J4: =4*B4 + 8*CEILING(LOG(C4,2),1) | K4: 0 | L4: 1 | M4: =K4*characterization!$B$17 + L4*characterization!$B$15 | N4: =K4*characterization!$G$17 + L4*characterization!$G$15 | O4: =K4*characterization!$L$17 + L4*characterization!$L$15 | P4: 0 | Q4: 1 | R4: =P4*characterization!$B$17 + Q4*characterization!$B$15 | S4: =P4*characterization!$G$17 + Q4*characterization!$G$15 | T4: =P4*characterization!$L$17 + Q4*characterization!$L$15 | U4: =ROUND(1000000/(MAX(M4,R4) + characterization!$B$3), 0) | V4: =ROUND(1000000/(MAX(N4,S4) + characterization!$G$3), 0) | W4: =ROUND(1000000/(MAX(O4,T4) + characterization!$L$3), 0) | X4: clk_main | Y4: =IFERROR(VLOOKUP(X4, characterization!$A$29:$G$34, 4, FALSE), "") | Z4: =IFERROR(VLOOKUP(X4, characterization!$A$29:$G$34, 3, FALSE), "") | AA4: =IF(Z4="TT",M4,IF(Z4="FF",N4,IF(Z4="SS",O4,""))) | AB4: =IF(Z4="TT",R4,IF(Z4="FF",S4,IF(Z4="SS",T4,""))) | AC4: =IFERROR(VLOOKUP(X4, characterization!$A$29:$G$34, 4, FALSE)*0.3, "") | AD4: =AC4 + AA4 + AB4 | AF4: =IFERROR(Y4 - AD4 - VLOOKUP(X4, characterization!$A$29:$G$34, 6, FALSE) - VLOOKUP(X4, characterization!$A$29:$G$34, 7, FALSE), "") | AG4: SRAM macro (single-port, synchronous read). Storage = W*D bits goes to the macro, not flop count. Read latency = 1 cycle (data appears next clock). Replace this row's per-bit delay with vendor SRAM datasheet for accurate timing.
A5: gaxi_fifo_sync (REG=1, SRAM-backed) | B5: 512 | C5: 512 | H5: P1=W, P2=D | I5: =3*CEILING(LOG(C5,2),1) + 1 | J5: =B5*4 + CEILING(LOG(C5,2),1)*8 + 20 | K5: 0 | L5: 1 | M5: =K5*characterization!$B$17 + L5*characterization!$B$15 | N5: =K5*characterization!$G$17 + L5*characterization!$G$15 | O5: =K5*characterization!$L$17 + L5*characterization!$L$15 | P5: 0 | Q5: 1 | R5: =P5*characterization!$B$17 + Q5*characterization!$B$15 | S5: =P5*characterization!$G$17 + Q5*characterization!$G$15 | T5: =P5*characterization!$L$17 + Q5*characterization!$L$15 | U5: =ROUND(1000000/(MAX(M5,R5) + characterization!$B$3), 0) | V5: =ROUND(1000000/(MAX(N5,S5) + characterization!$G$3), 0) | W5: =ROUND(1000000/(MAX(O5,T5) + characterization!$L$3), 0) | X5: clk_main | Y5: =IFERROR(VLOOKUP(X5, characterization!$A$29:$G$34, 4, FALSE), "") | Z5: =IFERROR(VLOOKUP(X5, characterization!$A$29:$G$34, 3, FALSE), "") | AA5: =IF(Z5="TT",M5,IF(Z5="FF",N5,IF(Z5="SS",O5,""))) | AB5: =IF(Z5="TT",R5,IF(Z5="FF",S5,IF(Z5="SS",T5,""))) | AC5: =IFERROR(VLOOKUP(X5, characterization!$A$29:$G$34, 4, FALSE)*0.3, "") | AD5: =AC5 + AA5 + AB5 | AF5: =IFERROR(Y5 - AD5 - VLOOKUP(X5, characterization!$A$29:$G$34, 6, FALSE) - VLOOKUP(X5, characterization!$A$29:$G$34, 7, FALSE), "") | AG5: REGISTERED=1 + MEM_STYLE=BRAM: storage is in an SRAM/BRAM macro, not flops. Used only by SRAM controller units in STREAM/RAPIDS. Storage bits = W*D. fmax is limited by the SRAM macro clock-to-Q, not by std-cell timing.
A6: Building Blocks
A7: gaxi_skid_buffer | B7: 1 | C7: 2 | H7: P1=W, P2=D | I7: =B7*C7 + C7 + 2 | J7: =B7*C7*4 + 10 | K7: 1 | L7: 1 | M7: =K7*characterization!$B$17 + L7*characterization!$B$15 | N7: =K7*characterization!$G$17 + L7*characterization!$G$15 | O7: =K7*characterization!$L$17 + L7*characterization!$L$15 | P7: 0 | Q7: 0 | R7: =P7*characterization!$B$17 + Q7*characterization!$B$15 | S7: =P7*characterization!$G$17 + Q7*characterization!$G$15 | T7: =P7*characterization!$L$17 + Q7*characterization!$L$15 | U7: =ROUND(1000000/(MAX(M7,R7) + characterization!$B$3), 0) | V7: =ROUND(1000000/(MAX(N7,S7) + characterization!$G$3), 0) | W7: =ROUND(1000000/(MAX(O7,T7) + characterization!$L$3), 0) | X7: clk_main | Y7: =IFERROR(VLOOKUP(X7, characterization!$A$29:$G$34, 4, FALSE), "") | Z7: =IFERROR(VLOOKUP(X7, characterization!$A$29:$G$34, 3, FALSE), "") | AA7: =IF(Z7="TT",M7,IF(Z7="FF",N7,IF(Z7="SS",O7,""))) | AB7: =IF(Z7="TT",R7,IF(Z7="FF",S7,IF(Z7="SS",T7,""))) | AC7: =IFERROR(VLOOKUP(X7, characterization!$A$29:$G$34, 4, FALSE)*0.3, "") | AD7: =AC7 + AA7 + AB7 | AF7: =IFERROR(Y7 - AD7 - VLOOKUP(X7, characterization!$A$29:$G$34, 6, FALSE) - VLOOKUP(X7, characterization!$A$29:$G$34, 7, FALSE), "") | AG7: Skid buffer outputs come straight from the head flop Q - no output muxing. Input side has the bypass MUX2. Flops = W*D storage + D valid + 2 control.
A8: gaxi_fifo_sync (REG=0) | B8: 1 | C8: 2 | H8: P1=W, P2=D | I8: =B8*C8 + 3*CEILING(LOG(C8,2),1) + 1 | J8: =B8*C8*6 + CEILING(LOG(C8,2),1)*8 + 20 | K8: 1 | L8: 2 | M8: =K8*characterization!$B$17 + L8*characterization!$B$15 | N8: =K8*characterization!$G$17 + L8*characterization!$G$15 | O8: =K8*characterization!$L$17 + L8*characterization!$L$15 | P8: =CEILING(LOG(C8,2),1) | Q8: 0 | R8: =P8*characterization!$B$17 + Q8*characterization!$B$15 | S8: =P8*characterization!$G$17 + Q8*characterization!$G$15 | T8: =P8*characterization!$L$17 + Q8*characterization!$L$15 | U8: =ROUND(1000000/(MAX(M8,R8) + characterization!$B$3), 0) | V8: =ROUND(1000000/(MAX(N8,S8) + characterization!$G$3), 0) | W8: =ROUND(1000000/(MAX(O8,T8) + characterization!$L$3), 0) | X8: clk_main | Y8: =IFERROR(VLOOKUP(X8, characterization!$A$29:$G$34, 4, FALSE), "") | Z8: =IFERROR(VLOOKUP(X8, characterization!$A$29:$G$34, 3, FALSE), "") | AA8: =IF(Z8="TT",M8,IF(Z8="FF",N8,IF(Z8="SS",O8,""))) | AB8: =IF(Z8="TT",R8,IF(Z8="FF",S8,IF(Z8="SS",T8,""))) | AC8: =IFERROR(VLOOKUP(X8, characterization!$A$29:$G$34, 4, FALSE)*0.3, "") | AD8: =AC8 + AA8 + AB8 | AF8: =IFERROR(Y8 - AD8 - VLOOKUP(X8, characterization!$A$29:$G$34, 6, FALSE) - VLOOKUP(X8, characterization!$A$29:$G$34, 7, FALSE), "") | AG8: Output critical path is the READ mux tree, depth=log2(D). Flops = W*D storage + 3*log2(D) ptrs/count + 1 state. Default FIFO in STREAM/RAPIDS (non-SRAM-backed).
A9: arbiter_round_robin | B9: 2 | H9: P1=N | I9: =B9 + 2 | J9: =B9*8 | K9: 0 | L9: 1 | M9: =K9*characterization!$B$17 + L9*characterization!$B$15 | N9: =K9*characterization!$G$17 + L9*characterization!$G$15 | O9: =K9*characterization!$L$17 + L9*characterization!$L$15 | P9: =CEILING(LOG(B9,2),1) | Q9: 1 | R9: =P9*characterization!$B$17 + Q9*characterization!$B$15 | S9: =P9*characterization!$G$17 + Q9*characterization!$G$15 | T9: =P9*characterization!$L$17 + Q9*characterization!$L$15 | U9: =ROUND(1000000/(MAX(M9,R9) + characterization!$B$3), 0) | V9: =ROUND(1000000/(MAX(N9,S9) + characterization!$G$3), 0) | W9: =ROUND(1000000/(MAX(O9,T9) + characterization!$L$3), 0) | X9: clk_main | Y9: =IFERROR(VLOOKUP(X9, characterization!$A$29:$G$34, 4, FALSE), "") | Z9: =IFERROR(VLOOKUP(X9, characterization!$A$29:$G$34, 3, FALSE), "") | AA9: =IF(Z9="TT",M9,IF(Z9="FF",N9,IF(Z9="SS",O9,""))) | AB9: =IF(Z9="TT",R9,IF(Z9="FF",S9,IF(Z9="SS",T9,""))) | AC9: =IFERROR(VLOOKUP(X9, characterization!$A$29:$G$34, 4, FALSE)*0.3, "") | AD9: =AC9 + AA9 + AB9 | AF9: =IFERROR(Y9 - AD9 - VLOOKUP(X9, characterization!$A$29:$G$34, 6, FALSE) - VLOOKUP(X9, characterization!$A$29:$G$34, 7, FALSE), "") | AG9: Priority encoder is log2(N) MUX levels on the OUTPUT side (req -> encode -> gnt). Flops = N (last-grant tracker) + 2.
A10: axi4_master_rd | B10: 32 | C10: 32 | D10: 4 | E10: 1 | F10: 2 | G10: 2 | H10: P1=AW, P2=DW, P3=IW, P4=UW, P5=SKID_AR, P6=SKID_R | I10: =F10*(B10+D10+E10+29) + G10*(D10+C10+E10+3) | J10: =4*(F10*(B10+D10+E10+29) + G10*(D10+C10+E10+3)) | K10: 1 | L10: 1 | M10: =K10*characterization!$B$17 + L10*characterization!$B$15 | N10: =K10*characterization!$G$17 + L10*characterization!$G$15 | O10: =K10*characterization!$L$17 + L10*characterization!$L$15 | P10: 1 | Q10: 1 | R10: =P10*characterization!$B$17 + Q10*characterization!$B$15 | S10: =P10*characterization!$G$17 + Q10*characterization!$G$15 | T10: =P10*characterization!$L$17 + Q10*characterization!$L$15 | U10: =ROUND(1000000/(MAX(M10,R10) + characterization!$B$3), 0) | V10: =ROUND(1000000/(MAX(N10,S10) + characterization!$G$3), 0) | W10: =ROUND(1000000/(MAX(O10,T10) + characterization!$L$3), 0) | X10: clk_main | Y10: =IFERROR(VLOOKUP(X10, characterization!$A$29:$G$34, 4, FALSE), "") | Z10: =IFERROR(VLOOKUP(X10, characterization!$A$29:$G$34, 3, FALSE), "") | AA10: =IF(Z10="TT",M10,IF(Z10="FF",N10,IF(Z10="SS",O10,""))) | AB10: =IF(Z10="TT",R10,IF(Z10="FF",S10,IF(Z10="SS",T10,""))) | AC10: =IFERROR(VLOOKUP(X10, characterization!$A$29:$G$34, 4, FALSE)*0.3, "") | AD10: =AC10 + AA10 + AB10 | AF10: =IFERROR(Y10 - AD10 - VLOOKUP(X10, characterization!$A$29:$G$34, 6, FALSE) - VLOOKUP(X10, characterization!$A$29:$G$34, 7, FALSE), "") | AG10: Two skid buffers in series (AR + R). Input bypass MUX2 + output select MUX2. Flops scale with SKID_AR*ARw + SKID_R*Rw.
A11: axi4_master_wr | B11: 32 | C11: 32 | D11: 4 | E11: 1 | F11: 2 | G11: 2 | H11: P1=AW, P2=DW, P3=IW, P4=UW, P5=SKID_AW, P6=SKID_W | I11: =F11*(B11+D11+E11+29) + G11*(C11+C11/8+E11+1) + 2*(D11+E11+2) | J11: =4*(F11*(B11+D11+E11+29) + G11*(C11+C11/8+E11+1) + 2*(D11+E11+2)) | K11: 1 | L11: 1 | M11: =K11*characterization!$B$17 + L11*characterization!$B$15 | N11: =K11*characterization!$G$17 + L11*characterization!$G$15 | O11: =K11*characterization!$L$17 + L11*characterization!$L$15 | P11: 1 | Q11: 1 | R11: =P11*characterization!$B$17 + Q11*characterization!$B$15 | S11: =P11*characterization!$G$17 + Q11*characterization!$G$15 | T11: =P11*characterization!$L$17 + Q11*characterization!$L$15 | U11: =ROUND(1000000/(MAX(M11,R11) + characterization!$B$3), 0) | V11: =ROUND(1000000/(MAX(N11,S11) + characterization!$G$3), 0) | W11: =ROUND(1000000/(MAX(O11,T11) + characterization!$L$3), 0) | X11: clk_main | Y11: =IFERROR(VLOOKUP(X11, characterization!$A$29:$G$34, 4, FALSE), "") | Z11: =IFERROR(VLOOKUP(X11, characterization!$A$29:$G$34, 3, FALSE), "") | AA11: =IF(Z11="TT",M11,IF(Z11="FF",N11,IF(Z11="SS",O11,""))) | AB11: =IF(Z11="TT",R11,IF(Z11="FF",S11,IF(Z11="SS",T11,""))) | AC11: =IFERROR(VLOOKUP(X11, characterization!$A$29:$G$34, 4, FALSE)*0.3, "") | AD11: =AC11 + AA11 + AB11 | AF11: =IFERROR(Y11 - AD11 - VLOOKUP(X11, characterization!$A$29:$G$34, 6, FALSE) - VLOOKUP(X11, characterization!$A$29:$G$34, 7, FALSE), "") | AG11: Three skid buffers (AW + W + B); SKID_B fixed at 2 in this row. Input bypass + output select MUXes; both are 1 level.
A13: SRAM storage size reference
A14: SRAM raw macro: storage bits = W * D = | D14: =B4*C4 | E14: bits = | F14: =B4*C4/8/1024 | G14: KB
A15: FIFO REG=1 SRAM-backed: storage bits = W * D = | D15: =B5*C5 | E15: bits = | F15: =B5*C5/8/1024 | G15: KB
A17: Cell coding
A18: Yellow = editable param
A19: Grey = derived formula
A21: data->D = critical combinational delay on the path that loads the downstream flop. Compare against (period - Tflop) to size for a freq.
A22: Estimates are first-order: structural flop/gate counts + characterization per-level delays. Treat them as design-time SWAGs, not post-synth truth.
A23: REG=1 SRAM-backed FIFO is only used by SRAM controller units in STREAM/RAPIDS (sram_controller_unit, src/snk_sram_controller_unit_beats). Everywhere else uses REG=0 - that's why the Building Blocks section lists only the REG=0 variant.

Sheet stream
A1: FUB | B1: port | C1: clock | D1: dir | E1: building block crossed | F1: MUX lv | G1: NAND lv | H1: source/sink flop or BB port | I1: target period (ps) | J1: target corner | K1: local delay (ps) | L1: delay_in (ps) | M1: delay_out (ps) | O1: slack (ps) | P1: places it goes (consumer / producer)
A2: CONFIG | B2: clock cell holds a name from characterization!Design clocks table (default clk_main). Period & corner are VLOOKUP'd per row. delay_in defaults to 60% of target period; slack reserves 40% for output delay.
A3: stream_latency_bridge
A4: stream_latency_bridge | B4: s_valid | C4: clk_main | D4: in | F4: 1 | G4: 1 | H4: r_drain_ip (D) | I4: =IFERROR(VLOOKUP(C4, characterization!$A$29:$G$34, 4, FALSE), "") | J4: =IFERROR(VLOOKUP(C4, characterization!$A$29:$G$34, 3, FALSE), "") | K4: =F4*IF(J4="TT",characterization!$B$17,IF(J4="FF",characterization!$G$17,characterization!$L$17))+G4*IF(J4="TT",characterization!$B$15,IF(J4="FF",characterization!$G$15,characterization!$L$15)) | L4: =IFERROR(VLOOKUP(C4, characterization!$A$29:$G$34, 4, FALSE)*0.3, "") | M4: =L4 + K4 | O4: =IFERROR(I4 - M4 - VLOOKUP(C4, characterization!$A$29:$G$34, 6, FALSE) - VLOOKUP(C4, characterization!$A$29:$G$34, 7, FALSE), "") | P4: from u_channel_fifo.rd_valid in sram_controller_unit
A5: stream_latency_bridge | B5: s_data[DW-1:0] | C5: clk_main | D5: in | E5: gaxi_fifo_sync | F5: 0 | G5: 0 | H5: u_skid_buffer.wr_data | I5: =IFERROR(VLOOKUP(C5, characterization!$A$29:$G$34, 4, FALSE), "") | J5: =IFERROR(VLOOKUP(C5, characterization!$A$29:$G$34, 3, FALSE), "") | K5: =F5*IF(J5="TT",characterization!$B$17,IF(J5="FF",characterization!$G$17,characterization!$L$17))+G5*IF(J5="TT",characterization!$B$15,IF(J5="FF",characterization!$G$15,characterization!$L$15)) | L5: =IFERROR(VLOOKUP(C5, characterization!$A$29:$G$34, 4, FALSE)*0.3, "") | M5: =L5 + K5 | O5: =IFERROR(I5 - M5 - VLOOKUP(C5, characterization!$A$29:$G$34, 6, FALSE) - VLOOKUP(C5, characterization!$A$29:$G$34, 7, FALSE), "") | P5: from u_channel_fifo.rd_data
A6: stream_latency_bridge | B6: r_drain_ip | C6: clk_main | D6: local | F6: 0 | G6: 0 | H6: u_skid_buffer.wr_valid (D) | I6: =IFERROR(VLOOKUP(C6, characterization!$A$29:$G$34, 4, FALSE), "") | J6: =IFERROR(VLOOKUP(C6, characterization!$A$29:$G$34, 3, FALSE), "") | K6: =F6*IF(J6="TT",characterization!$B$17,IF(J6="FF",characterization!$G$17,characterization!$L$17))+G6*IF(J6="TT",characterization!$B$15,IF(J6="FF",characterization!$G$15,characterization!$L$15)) | L6: =IFERROR(VLOOKUP(C6, characterization!$A$29:$G$34, 4, FALSE)*0.3, "") | M6: =L6 + K6 | O6: =IFERROR(I6 - M6 - VLOOKUP(C6, characterization!$A$29:$G$34, 6, FALSE) - VLOOKUP(C6, characterization!$A$29:$G$34, 7, FALSE), "") | P6: internal: only local flop; gates the skid push
A7: stream_latency_bridge | B7: s_ready | C7: clk_main | D7: out | F7: 1 | G7: 2 | H7: comb of u_skid_buffer.count + r_drain_ip | I7: =IFERROR(VLOOKUP(C7, characterization!$A$29:$G$34, 4, FALSE), "") | J7: =IFERROR(VLOOKUP(C7, characterization!$A$29:$G$34, 3, FALSE), "") | K7: =F7*IF(J7="TT",characterization!$B$17,IF(J7="FF",characterization!$G$17,characterization!$L$17))+G7*IF(J7="TT",characterization!$B$15,IF(J7="FF",characterization!$G$15,characterization!$L$15)) | L7: =IFERROR(VLOOKUP(C7, characterization!$A$29:$G$34, 4, FALSE)*0.3, "") | M7: =L7 + K7 | O7: =IFERROR(I7 - M7 - VLOOKUP(C7, characterization!$A$29:$G$34, 6, FALSE) - VLOOKUP(C7, characterization!$A$29:$G$34, 7, FALSE), "") | P7: to u_channel_fifo.rd_ready
A8: stream_latency_bridge | B8: m_valid | C8: clk_main | D8: out | E8: gaxi_fifo_sync | F8: 0 | G8: 0 | H8: u_skid_buffer.rd_valid (Q) | I8: =IFERROR(VLOOKUP(C8, characterization!$A$29:$G$34, 4, FALSE), "") | J8: =IFERROR(VLOOKUP(C8, characterization!$A$29:$G$34, 3, FALSE), "") | K8: =F8*IF(J8="TT",characterization!$B$17,IF(J8="FF",characterization!$G$17,characterization!$L$17))+G8*IF(J8="TT",characterization!$B$15,IF(J8="FF",characterization!$G$15,characterization!$L$15)) | L8: =IFERROR(VLOOKUP(C8, characterization!$A$29:$G$34, 4, FALSE)*0.3, "") | M8: =L8 + K8 | O8: =IFERROR(I8 - M8 - VLOOKUP(C8, characterization!$A$29:$G$34, 6, FALSE) - VLOOKUP(C8, characterization!$A$29:$G$34, 7, FALSE), "") | P8: to sram_controller_unit.axi_wr_sram_valid -> axi_write_engine
A9: stream_latency_bridge | B9: m_data[DW-1:0] | C9: clk_main | D9: out | E9: gaxi_fifo_sync | F9: 0 | G9: 0 | H9: u_skid_buffer.rd_data (Q) | I9: =IFERROR(VLOOKUP(C9, characterization!$A$29:$G$34, 4, FALSE), "") | J9: =IFERROR(VLOOKUP(C9, characterization!$A$29:$G$34, 3, FALSE), "") | K9: =F9*IF(J9="TT",characterization!$B$17,IF(J9="FF",characterization!$G$17,characterization!$L$17))+G9*IF(J9="TT",characterization!$B$15,IF(J9="FF",characterization!$G$15,characterization!$L$15)) | L9: =IFERROR(VLOOKUP(C9, characterization!$A$29:$G$34, 4, FALSE)*0.3, "") | M9: =L9 + K9 | O9: =IFERROR(I9 - M9 - VLOOKUP(C9, characterization!$A$29:$G$34, 6, FALSE) - VLOOKUP(C9, characterization!$A$29:$G$34, 7, FALSE), "") | P9: to sram_controller_unit.axi_wr_sram_data -> axi_write_engine
A10: stream_latency_bridge | B10: m_ready | C10: clk_main | D10: in | E10: gaxi_fifo_sync | F10: 0 | G10: 0 | H10: u_skid_buffer.rd_ready | I10: =IFERROR(VLOOKUP(C10, characterization!$A$29:$G$34, 4, FALSE), "") | J10: =IFERROR(VLOOKUP(C10, characterization!$A$29:$G$34, 3, FALSE), "") | K10: =F10*IF(J10="TT",characterization!$B$17,IF(J10="FF",characterization!$G$17,characterization!$L$17))+G10*IF(J10="TT",characterization!$B$15,IF(J10="FF",characterization!$G$15,characterization!$L$15)) | L10: =IFERROR(VLOOKUP(C10, characterization!$A$29:$G$34, 4, FALSE)*0.3, "") | M10: =L10 + K10 | O10: =IFERROR(I10 - M10 - VLOOKUP(C10, characterization!$A$29:$G$34, 6, FALSE) - VLOOKUP(C10, characterization!$A$29:$G$34, 7, FALSE), "") | P10: from axi_write_engine via sram_controller_unit
A11: stream_latency_bridge | B11: occupancy[2:0] | C11: clk_main | D11: out | E11: gaxi_fifo_sync | F11: 0 | G11: 0 | H11: u_skid_buffer.count (Q) | I11: =IFERROR(VLOOKUP(C11, characterization!$A$29:$G$34, 4, FALSE), "") | J11: =IFERROR(VLOOKUP(C11, characterization!$A$29:$G$34, 3, FALSE), "") | K11: =F11*IF(J11="TT",characterization!$B$17,IF(J11="FF",characterization!$G$17,characterization!$L$17))+G11*IF(J11="TT",characterization!$B$15,IF(J11="FF",characterization!$G$15,characterization!$L$15)) | L11: =IFERROR(VLOOKUP(C11, characterization!$A$29:$G$34, 4, FALSE)*0.3, "") | M11: =L11 + K11 | O11: =IFERROR(I11 - M11 - VLOOKUP(C11, characterization!$A$29:$G$34, 6, FALSE) - VLOOKUP(C11, characterization!$A$29:$G$34, 7, FALSE), "") | P11: to scheduler (drain-IP backpressure)
A12: stream_latency_bridge | B12: dbg_r_pending | C12: clk_main | D12: out | F12: 0 | G12: 0 | H12: r_drain_ip (Q) | I12: =IFERROR(VLOOKUP(C12, characterization!$A$29:$G$34, 4, FALSE), "") | J12: =IFERROR(VLOOKUP(C12, characterization!$A$29:$G$34, 3, FALSE), "") | K12: =F12*IF(J12="TT",characterization!$B$17,IF(J12="FF",characterization!$G$17,characterization!$L$17))+G12*IF(J12="TT",characterization!$B$15,IF(J12="FF",characterization!$G$15,characterization!$L$15)) | L12: =IFERROR(VLOOKUP(C12, characterization!$A$29:$G$34, 4, FALSE)*0.3, "") | M12: =L12 + K12 | O12: =IFERROR(I12 - M12 - VLOOKUP(C12, characterization!$A$29:$G$34, 6, FALSE) - VLOOKUP(C12, characterization!$A$29:$G$34, 7, FALSE), "") | P12: debug observability
A13: stream_alloc_ctrl
A14: stream_alloc_ctrl | B14: wr_valid | C14: clk_main | D14: in | F14: 0 | G14: 1 | H14: r_wr_ptr (D) | I14: =IFERROR(VLOOKUP(C14, characterization!$A$29:$G$34, 4, FALSE), "") | J14: =IFERROR(VLOOKUP(C14, characterization!$A$29:$G$34, 3, FALSE), "") | K14: =F14*IF(J14="TT",characterization!$B$17,IF(J14="FF",characterization!$G$17,characterization!$L$17))+G14*IF(J14="TT",characterization!$B$15,IF(J14="FF",characterization!$G$15,characterization!$L$15)) | L14: =IFERROR(VLOOKUP(C14, characterization!$A$29:$G$34, 4, FALSE)*0.3, "") | M14: =L14 + K14 | O14: =IFERROR(I14 - M14 - VLOOKUP(C14, characterization!$A$29:$G$34, 6, FALSE) - VLOOKUP(C14, characterization!$A$29:$G$34, 7, FALSE), "") | P14: from axi_read_engine (allocate request)
A15: stream_alloc_ctrl | B15: wr_size[7:0] | C15: clk_main | D15: in | F15: 0 | G15: 1 | H15: r_wr_ptr adder input | I15: =IFERROR(VLOOKUP(C15, characterization!$A$29:$G$34, 4, FALSE), "") | J15: =IFERROR(VLOOKUP(C15, characterization!$A$29:$G$34, 3, FALSE), "") | K15: =F15*IF(J15="TT",characterization!$B$17,IF(J15="FF",characterization!$G$17,characterization!$L$17))+G15*IF(J15="TT",characterization!$B$15,IF(J15="FF",characterization!$G$15,characterization!$L$15)) | L15: =IFERROR(VLOOKUP(C15, characterization!$A$29:$G$34, 4, FALSE)*0.3, "") | M15: =L15 + K15 | O15: =IFERROR(I15 - M15 - VLOOKUP(C15, characterization!$A$29:$G$34, 6, FALSE) - VLOOKUP(C15, characterization!$A$29:$G$34, 7, FALSE), "") | P15: from axi_read_engine
A16: stream_alloc_ctrl | B16: rd_valid | C16: clk_main | D16: in | F16: 0 | G16: 1 | H16: r_rd_ptr (D) | I16: =IFERROR(VLOOKUP(C16, characterization!$A$29:$G$34, 4, FALSE), "") | J16: =IFERROR(VLOOKUP(C16, characterization!$A$29:$G$34, 3, FALSE), "") | K16: =F16*IF(J16="TT",characterization!$B$17,IF(J16="FF",characterization!$G$17,characterization!$L$17))+G16*IF(J16="TT",characterization!$B$15,IF(J16="FF",characterization!$G$15,characterization!$L$15)) | L16: =IFERROR(VLOOKUP(C16, characterization!$A$29:$G$34, 4, FALSE)*0.3, "") | M16: =L16 + K16 | O16: =IFERROR(I16 - M16 - VLOOKUP(C16, characterization!$A$29:$G$34, 6, FALSE) - VLOOKUP(C16, characterization!$A$29:$G$34, 7, FALSE), "") | P16: from sram_controller_unit (release event)
A17: stream_alloc_ctrl | B17: r_wr_ptr | C17: clk_main | D17: local | F17: 0 | G17: 1 | H17: r_space_free (D) | I17: =IFERROR(VLOOKUP(C17, characterization!$A$29:$G$34, 4, FALSE), "") | J17: =IFERROR(VLOOKUP(C17, characterization!$A$29:$G$34, 3, FALSE), "") | K17: =F17*IF(J17="TT",characterization!$B$17,IF(J17="FF",characterization!$G$17,characterization!$L$17))+G17*IF(J17="TT",characterization!$B$15,IF(J17="FF",characterization!$G$15,characterization!$L$15)) | L17: =IFERROR(VLOOKUP(C17, characterization!$A$29:$G$34, 4, FALSE)*0.3, "") | M17: =L17 + K17 | O17: =IFERROR(I17 - M17 - VLOOKUP(C17, characterization!$A$29:$G$34, 6, FALSE) - VLOOKUP(C17, characterization!$A$29:$G$34, 7, FALSE), "") | P17: internal: wr_ptr - rd_ptr = space_free
A18: stream_alloc_ctrl | B18: r_rd_ptr | C18: clk_main | D18: local | F18: 0 | G18: 1 | H18: r_space_free (D) | I18: =IFERROR(VLOOKUP(C18, characterization!$A$29:$G$34, 4, FALSE), "") | J18: =IFERROR(VLOOKUP(C18, characterization!$A$29:$G$34, 3, FALSE), "") | K18: =F18*IF(J18="TT",characterization!$B$17,IF(J18="FF",characterization!$G$17,characterization!$L$17))+G18*IF(J18="TT",characterization!$B$15,IF(J18="FF",characterization!$G$15,characterization!$L$15)) | L18: =IFERROR(VLOOKUP(C18, characterization!$A$29:$G$34, 4, FALSE)*0.3, "") | M18: =L18 + K18 | O18: =IFERROR(I18 - M18 - VLOOKUP(C18, characterization!$A$29:$G$34, 6, FALSE) - VLOOKUP(C18, characterization!$A$29:$G$34, 7, FALSE), "") | P18: internal: subtractor into space_free
A19: stream_alloc_ctrl | B19: r_space_free | C19: clk_main | D19: local | F19: 0 | G19: 1 | H19: r_wr_full (D) | I19: =IFERROR(VLOOKUP(C19, characterization!$A$29:$G$34, 4, FALSE), "") | J19: =IFERROR(VLOOKUP(C19, characterization!$A$29:$G$34, 3, FALSE), "") | K19: =F19*IF(J19="TT",characterization!$B$17,IF(J19="FF",characterization!$G$17,characterization!$L$17))+G19*IF(J19="TT",characterization!$B$15,IF(J19="FF",characterization!$G$15,characterization!$L$15)) | L19: =IFERROR(VLOOKUP(C19, characterization!$A$29:$G$34, 4, FALSE)*0.3, "") | M19: =L19 + K19 | O19: =IFERROR(I19 - M19 - VLOOKUP(C19, characterization!$A$29:$G$34, 6, FALSE) - VLOOKUP(C19, characterization!$A$29:$G$34, 7, FALSE), "") | P19: internal: cmp against DEPTH for full/almost_full flops
A20: stream_alloc_ctrl | B20: space_free[AW:0] | C20: clk_main | D20: out | F20: 0 | G20: 0 | H20: r_space_free (Q) | I20: =IFERROR(VLOOKUP(C20, characterization!$A$29:$G$34, 4, FALSE), "") | J20: =IFERROR(VLOOKUP(C20, characterization!$A$29:$G$34, 3, FALSE), "") | K20: =F20*IF(J20="TT",characterization!$B$17,IF(J20="FF",characterization!$G$17,characterization!$L$17))+G20*IF(J20="TT",characterization!$B$15,IF(J20="FF",characterization!$G$15,characterization!$L$15)) | L20: =IFERROR(VLOOKUP(C20, characterization!$A$29:$G$34, 4, FALSE)*0.3, "") | M20: =L20 + K20 | O20: =IFERROR(I20 - M20 - VLOOKUP(C20, characterization!$A$29:$G$34, 6, FALSE) - VLOOKUP(C20, characterization!$A$29:$G$34, 7, FALSE), "") | P20: to axi_read_engine (sram_alloc_space_free)
A21: stream_alloc_ctrl | B21: wr_full | C21: clk_main | D21: out | F21: 0 | G21: 0 | H21: r_wr_full (Q) | I21: =IFERROR(VLOOKUP(C21, characterization!$A$29:$G$34, 4, FALSE), "") | J21: =IFERROR(VLOOKUP(C21, characterization!$A$29:$G$34, 3, FALSE), "") | K21: =F21*IF(J21="TT",characterization!$B$17,IF(J21="FF",characterization!$G$17,characterization!$L$17))+G21*IF(J21="TT",characterization!$B$15,IF(J21="FF",characterization!$G$15,characterization!$L$15)) | L21: =IFERROR(VLOOKUP(C21, characterization!$A$29:$G$34, 4, FALSE)*0.3, "") | M21: =L21 + K21 | O21: =IFERROR(I21 - M21 - VLOOKUP(C21, characterization!$A$29:$G$34, 6, FALSE) - VLOOKUP(C21, characterization!$A$29:$G$34, 7, FALSE), "") | P21: to axi_read_engine (back-pressure)
A22: stream_alloc_ctrl | B22: wr_almost_full | C22: clk_main | D22: out | F22: 0 | G22: 0 | H22: r_wr_almost_full (Q) | I22: =IFERROR(VLOOKUP(C22, characterization!$A$29:$G$34, 4, FALSE), "") | J22: =IFERROR(VLOOKUP(C22, characterization!$A$29:$G$34, 3, FALSE), "") | K22: =F22*IF(J22="TT",characterization!$B$17,IF(J22="FF",characterization!$G$17,characterization!$L$17))+G22*IF(J22="TT",characterization!$B$15,IF(J22="FF",characterization!$G$15,characterization!$L$15)) | L22: =IFERROR(VLOOKUP(C22, characterization!$A$29:$G$34, 4, FALSE)*0.3, "") | M22: =L22 + K22 | O22: =IFERROR(I22 - M22 - VLOOKUP(C22, characterization!$A$29:$G$34, 6, FALSE) - VLOOKUP(C22, characterization!$A$29:$G$34, 7, FALSE), "") | P22: to axi_read_engine (threshold)
A23: stream_drain_ctrl
A24: stream_drain_ctrl | B24: wr_valid | C24: clk_main | D24: in | F24: 0 | G24: 1 | H24: r_wr_ptr (D) | I24: =IFERROR(VLOOKUP(C24, characterization!$A$29:$G$34, 4, FALSE), "") | J24: =IFERROR(VLOOKUP(C24, characterization!$A$29:$G$34, 3, FALSE), "") | K24: =F24*IF(J24="TT",characterization!$B$17,IF(J24="FF",characterization!$G$17,characterization!$L$17))+G24*IF(J24="TT",characterization!$B$15,IF(J24="FF",characterization!$G$15,characterization!$L$15)) | L24: =IFERROR(VLOOKUP(C24, characterization!$A$29:$G$34, 4, FALSE)*0.3, "") | M24: =L24 + K24 | O24: =IFERROR(I24 - M24 - VLOOKUP(C24, characterization!$A$29:$G$34, 6, FALSE) - VLOOKUP(C24, characterization!$A$29:$G$34, 7, FALSE), "") | P24: from u_channel_fifo handshake in sram_controller_unit
A25: stream_drain_ctrl | B25: rd_valid | C25: clk_main | D25: in | F25: 0 | G25: 1 | H25: r_rd_ptr (D) | I25: =IFERROR(VLOOKUP(C25, characterization!$A$29:$G$34, 4, FALSE), "") | J25: =IFERROR(VLOOKUP(C25, characterization!$A$29:$G$34, 3, FALSE), "") | K25: =F25*IF(J25="TT",characterization!$B$17,IF(J25="FF",characterization!$G$17,characterization!$L$17))+G25*IF(J25="TT",characterization!$B$15,IF(J25="FF",characterization!$G$15,characterization!$L$15)) | L25: =IFERROR(VLOOKUP(C25, characterization!$A$29:$G$34, 4, FALSE)*0.3, "") | M25: =L25 + K25 | O25: =IFERROR(I25 - M25 - VLOOKUP(C25, characterization!$A$29:$G$34, 6, FALSE) - VLOOKUP(C25, characterization!$A$29:$G$34, 7, FALSE), "") | P25: from axi_write_engine (drain reservation)
A26: stream_drain_ctrl | B26: rd_size[7:0] | C26: clk_main | D26: in | F26: 0 | G26: 1 | H26: r_rd_ptr adder input | I26: =IFERROR(VLOOKUP(C26, characterization!$A$29:$G$34, 4, FALSE), "") | J26: =IFERROR(VLOOKUP(C26, characterization!$A$29:$G$34, 3, FALSE), "") | K26: =F26*IF(J26="TT",characterization!$B$17,IF(J26="FF",characterization!$G$17,characterization!$L$17))+G26*IF(J26="TT",characterization!$B$15,IF(J26="FF",characterization!$G$15,characterization!$L$15)) | L26: =IFERROR(VLOOKUP(C26, characterization!$A$29:$G$34, 4, FALSE)*0.3, "") | M26: =L26 + K26 | O26: =IFERROR(I26 - M26 - VLOOKUP(C26, characterization!$A$29:$G$34, 6, FALSE) - VLOOKUP(C26, characterization!$A$29:$G$34, 7, FALSE), "") | P26: from axi_write_engine
A27: stream_drain_ctrl | B27: r_wr_ptr | C27: clk_main | D27: local | F27: 0 | G27: 1 | H27: r_data_available (D) | I27: =IFERROR(VLOOKUP(C27, characterization!$A$29:$G$34, 4, FALSE), "") | J27: =IFERROR(VLOOKUP(C27, characterization!$A$29:$G$34, 3, FALSE), "") | K27: =F27*IF(J27="TT",characterization!$B$17,IF(J27="FF",characterization!$G$17,characterization!$L$17))+G27*IF(J27="TT",characterization!$B$15,IF(J27="FF",characterization!$G$15,characterization!$L$15)) | L27: =IFERROR(VLOOKUP(C27, characterization!$A$29:$G$34, 4, FALSE)*0.3, "") | M27: =L27 + K27 | O27: =IFERROR(I27 - M27 - VLOOKUP(C27, characterization!$A$29:$G$34, 6, FALSE) - VLOOKUP(C27, characterization!$A$29:$G$34, 7, FALSE), "") | P27: internal: wr_ptr - rd_ptr = data_available
A28: stream_drain_ctrl | B28: r_rd_ptr | C28: clk_main | D28: local | F28: 0 | G28: 1 | H28: r_data_available (D) | I28: =IFERROR(VLOOKUP(C28, characterization!$A$29:$G$34, 4, FALSE), "") | J28: =IFERROR(VLOOKUP(C28, characterization!$A$29:$G$34, 3, FALSE), "") | K28: =F28*IF(J28="TT",characterization!$B$17,IF(J28="FF",characterization!$G$17,characterization!$L$17))+G28*IF(J28="TT",characterization!$B$15,IF(J28="FF",characterization!$G$15,characterization!$L$15)) | L28: =IFERROR(VLOOKUP(C28, characterization!$A$29:$G$34, 4, FALSE)*0.3, "") | M28: =L28 + K28 | O28: =IFERROR(I28 - M28 - VLOOKUP(C28, characterization!$A$29:$G$34, 6, FALSE) - VLOOKUP(C28, characterization!$A$29:$G$34, 7, FALSE), "") | P28: internal: subtractor into data_available
A29: stream_drain_ctrl | B29: r_data_available | C29: clk_main | D29: local | F29: 0 | G29: 1 | H29: r_rd_empty (D) | I29: =IFERROR(VLOOKUP(C29, characterization!$A$29:$G$34, 4, FALSE), "") | J29: =IFERROR(VLOOKUP(C29, characterization!$A$29:$G$34, 3, FALSE), "") | K29: =F29*IF(J29="TT",characterization!$B$17,IF(J29="FF",characterization!$G$17,characterization!$L$17))+G29*IF(J29="TT",characterization!$B$15,IF(J29="FF",characterization!$G$15,characterization!$L$15)) | L29: =IFERROR(VLOOKUP(C29, characterization!$A$29:$G$34, 4, FALSE)*0.3, "") | M29: =L29 + K29 | O29: =IFERROR(I29 - M29 - VLOOKUP(C29, characterization!$A$29:$G$34, 6, FALSE) - VLOOKUP(C29, characterization!$A$29:$G$34, 7, FALSE), "") | P29: internal: cmp 0 / cmp DEPTH for empty / full flops
A30: stream_drain_ctrl | B30: data_available[AW:0] | C30: clk_main | D30: out | F30: 0 | G30: 0 | H30: r_data_available (Q) | I30: =IFERROR(VLOOKUP(C30, characterization!$A$29:$G$34, 4, FALSE), "") | J30: =IFERROR(VLOOKUP(C30, characterization!$A$29:$G$34, 3, FALSE), "") | K30: =F30*IF(J30="TT",characterization!$B$17,IF(J30="FF",characterization!$G$17,characterization!$L$17))+G30*IF(J30="TT",characterization!$B$15,IF(J30="FF",characterization!$G$15,characterization!$L$15)) | L30: =IFERROR(VLOOKUP(C30, characterization!$A$29:$G$34, 4, FALSE)*0.3, "") | M30: =L30 + K30 | O30: =IFERROR(I30 - M30 - VLOOKUP(C30, characterization!$A$29:$G$34, 6, FALSE) - VLOOKUP(C30, characterization!$A$29:$G$34, 7, FALSE), "") | P30: to axi_write_engine
A31: stream_drain_ctrl | B31: rd_empty | C31: clk_main | D31: out | F31: 0 | G31: 0 | H31: r_rd_empty (Q) | I31: =IFERROR(VLOOKUP(C31, characterization!$A$29:$G$34, 4, FALSE), "") | J31: =IFERROR(VLOOKUP(C31, characterization!$A$29:$G$34, 3, FALSE), "") | K31: =F31*IF(J31="TT",characterization!$B$17,IF(J31="FF",characterization!$G$17,characterization!$L$17))+G31*IF(J31="TT",characterization!$B$15,IF(J31="FF",characterization!$G$15,characterization!$L$15)) | L31: =IFERROR(VLOOKUP(C31, characterization!$A$29:$G$34, 4, FALSE)*0.3, "") | M31: =L31 + K31 | O31: =IFERROR(I31 - M31 - VLOOKUP(C31, characterization!$A$29:$G$34, 6, FALSE) - VLOOKUP(C31, characterization!$A$29:$G$34, 7, FALSE), "") | P31: to axi_write_engine (no data)
A32: stream_drain_ctrl | B32: wr_full | C32: clk_main | D32: out | F32: 0 | G32: 0 | H32: r_wr_full (Q) | I32: =IFERROR(VLOOKUP(C32, characterization!$A$29:$G$34, 4, FALSE), "") | J32: =IFERROR(VLOOKUP(C32, characterization!$A$29:$G$34, 3, FALSE), "") | K32: =F32*IF(J32="TT",characterization!$B$17,IF(J32="FF",characterization!$G$17,characterization!$L$17))+G32*IF(J32="TT",characterization!$B$15,IF(J32="FF",characterization!$G$15,characterization!$L$15)) | L32: =IFERROR(VLOOKUP(C32, characterization!$A$29:$G$34, 4, FALSE)*0.3, "") | M32: =L32 + K32 | O32: =IFERROR(I32 - M32 - VLOOKUP(C32, characterization!$A$29:$G$34, 6, FALSE) - VLOOKUP(C32, characterization!$A$29:$G$34, 7, FALSE), "") | P32: to sram_controller_unit (back-pressure)
A33: sram_controller_unit
A34: sram_controller_unit | B34: axi_rd_alloc_req | C34: clk_main | D34: in | F34: 0 | G34: 1 | H34: u_alloc_ctrl.wr_valid | I34: =IFERROR(VLOOKUP(C34, characterization!$A$29:$G$34, 4, FALSE), "") | J34: =IFERROR(VLOOKUP(C34, characterization!$A$29:$G$34, 3, FALSE), "") | K34: =F34*IF(J34="TT",characterization!$B$17,IF(J34="FF",characterization!$G$17,characterization!$L$17))+G34*IF(J34="TT",characterization!$B$15,IF(J34="FF",characterization!$G$15,characterization!$L$15)) | L34: =IFERROR(VLOOKUP(C34, characterization!$A$29:$G$34, 4, FALSE)*0.3, "") | M34: =L34 + K34 | O34: =IFERROR(I34 - M34 - VLOOKUP(C34, characterization!$A$29:$G$34, 6, FALSE) - VLOOKUP(C34, characterization!$A$29:$G$34, 7, FALSE), "") | P34: from axi_read_engine (reserve burst space)
A35: sram_controller_unit | B35: axi_rd_alloc_size[7:0] | C35: clk_main | D35: in | F35: 0 | G35: 0 | H35: u_alloc_ctrl.wr_size | I35: =IFERROR(VLOOKUP(C35, characterization!$A$29:$G$34, 4, FALSE), "") | J35: =IFERROR(VLOOKUP(C35, characterization!$A$29:$G$34, 3, FALSE), "") | K35: =F35*IF(J35="TT",characterization!$B$17,IF(J35="FF",characterization!$G$17,characterization!$L$17))+G35*IF(J35="TT",characterization!$B$15,IF(J35="FF",characterization!$G$15,characterization!$L$15)) | L35: =IFERROR(VLOOKUP(C35, characterization!$A$29:$G$34, 4, FALSE)*0.3, "") | M35: =L35 + K35 | O35: =IFERROR(I35 - M35 - VLOOKUP(C35, characterization!$A$29:$G$34, 6, FALSE) - VLOOKUP(C35, characterization!$A$29:$G$34, 7, FALSE), "") | P35: from axi_read_engine
A36: sram_controller_unit | B36: r_axi_wr_sram_valid | C36: clk_main | D36: local | F36: 0 | G36: 0 | H36: axi_wr_sram_valid (Q) | I36: =IFERROR(VLOOKUP(C36, characterization!$A$29:$G$34, 4, FALSE), "") | J36: =IFERROR(VLOOKUP(C36, characterization!$A$29:$G$34, 3, FALSE), "") | K36: =F36*IF(J36="TT",characterization!$B$17,IF(J36="FF",characterization!$G$17,characterization!$L$17))+G36*IF(J36="TT",characterization!$B$15,IF(J36="FF",characterization!$G$15,characterization!$L$15)) | L36: =IFERROR(VLOOKUP(C36, characterization!$A$29:$G$34, 4, FALSE)*0.3, "") | M36: =L36 + K36 | O36: =IFERROR(I36 - M36 - VLOOKUP(C36, characterization!$A$29:$G$34, 6, FALSE) - VLOOKUP(C36, characterization!$A$29:$G$34, 7, FALSE), "") | P36: registers latency_bridge.m_valid before driving the boundary
A37: sram_controller_unit | B37: axi_rd_alloc_space_free[AW:0] | C37: clk_main | D37: out | F37: 0 | G37: 0 | H37: u_alloc_ctrl.space_free (Q) | I37: =IFERROR(VLOOKUP(C37, characterization!$A$29:$G$34, 4, FALSE), "") | J37: =IFERROR(VLOOKUP(C37, characterization!$A$29:$G$34, 3, FALSE), "") | K37: =F37*IF(J37="TT",characterization!$B$17,IF(J37="FF",characterization!$G$17,characterization!$L$17))+G37*IF(J37="TT",characterization!$B$15,IF(J37="FF",characterization!$G$15,characterization!$L$15)) | L37: =IFERROR(VLOOKUP(C37, characterization!$A$29:$G$34, 4, FALSE)*0.3, "") | M37: =L37 + K37 | O37: =IFERROR(I37 - M37 - VLOOKUP(C37, characterization!$A$29:$G$34, 6, FALSE) - VLOOKUP(C37, characterization!$A$29:$G$34, 7, FALSE), "") | P37: to axi_read_engine
A38: sram_controller_unit | B38: axi_rd_sram_valid | C38: clk_main | D38: in | E38: gaxi_fifo_sync | F38: 0 | G38: 0 | H38: u_channel_fifo.wr_valid | I38: =IFERROR(VLOOKUP(C38, characterization!$A$29:$G$34, 4, FALSE), "") | J38: =IFERROR(VLOOKUP(C38, characterization!$A$29:$G$34, 3, FALSE), "") | K38: =F38*IF(J38="TT",characterization!$B$17,IF(J38="FF",characterization!$G$17,characterization!$L$17))+G38*IF(J38="TT",characterization!$B$15,IF(J38="FF",characterization!$G$15,characterization!$L$15)) | L38: =IFERROR(VLOOKUP(C38, characterization!$A$29:$G$34, 4, FALSE)*0.3, "") | M38: =L38 + K38 | O38: =IFERROR(I38 - M38 - VLOOKUP(C38, characterization!$A$29:$G$34, 6, FALSE) - VLOOKUP(C38, characterization!$A$29:$G$34, 7, FALSE), "") | P38: from axi_read_engine (write data into SRAM FIFO)
A39: sram_controller_unit | B39: axi_rd_sram_data[DW-1:0] | C39: clk_main | D39: in | E39: gaxi_fifo_sync | F39: 0 | G39: 0 | H39: u_channel_fifo.wr_data | I39: =IFERROR(VLOOKUP(C39, characterization!$A$29:$G$34, 4, FALSE), "") | J39: =IFERROR(VLOOKUP(C39, characterization!$A$29:$G$34, 3, FALSE), "") | K39: =F39*IF(J39="TT",characterization!$B$17,IF(J39="FF",characterization!$G$17,characterization!$L$17))+G39*IF(J39="TT",characterization!$B$15,IF(J39="FF",characterization!$G$15,characterization!$L$15)) | L39: =IFERROR(VLOOKUP(C39, characterization!$A$29:$G$34, 4, FALSE)*0.3, "") | M39: =L39 + K39 | O39: =IFERROR(I39 - M39 - VLOOKUP(C39, characterization!$A$29:$G$34, 6, FALSE) - VLOOKUP(C39, characterization!$A$29:$G$34, 7, FALSE), "") | P39: from axi_read_engine
A40: sram_controller_unit | B40: axi_rd_sram_ready | C40: clk_main | D40: out | E40: gaxi_fifo_sync | F40: 0 | G40: 0 | H40: u_channel_fifo.wr_ready (Q) | I40: =IFERROR(VLOOKUP(C40, characterization!$A$29:$G$34, 4, FALSE), "") | J40: =IFERROR(VLOOKUP(C40, characterization!$A$29:$G$34, 3, FALSE), "") | K40: =F40*IF(J40="TT",characterization!$B$17,IF(J40="FF",characterization!$G$17,characterization!$L$17))+G40*IF(J40="TT",characterization!$B$15,IF(J40="FF",characterization!$G$15,characterization!$L$15)) | L40: =IFERROR(VLOOKUP(C40, characterization!$A$29:$G$34, 4, FALSE)*0.3, "") | M40: =L40 + K40 | O40: =IFERROR(I40 - M40 - VLOOKUP(C40, characterization!$A$29:$G$34, 6, FALSE) - VLOOKUP(C40, characterization!$A$29:$G$34, 7, FALSE), "") | P40: to axi_read_engine
...
